Workbook

Sheet General Walk in Cooler
D3: Input Parameters | E3: Input Values | K3: Output Table
D4: Box Interior Temp (F) | E4: 35 | K4: Wall Load | N4: =O4/O9 -> 0.4171401 | O4: =(1/28.57)*(E5-E4)*(2*E9*G9+2*F9*G9+E9*F9)+IF(E10= "On Grade",Background!K4,IF(E10= "Above Grade",Background!K5,Background!K6)) -> 1979.3331 | R4: Safety Factor | S4: 10
D5: Box Exterior Temp (F) | E5: 85 | K5: Product Load | N5: =O5/O9 -> 0.13522984 | O5: =2*E9*F9*G9*0.77*10/24 -> 641.66667 | R5: System Run time | S5: 18
D6: Box Interior RH (%) | E6: 80 | K6: Miscellaneous Load | N6: =O6/O9 -> 0.21568528 | O6: =E9*F9*3.41+INDEX(Background!F4:F19, MATCH(E9*F9*G9, Background!C4:C19,1)) -> 1023.4284
D7: Box Exterior RH (%) | E7: 55 | K7: Infiltration Load | N7: =O7/O9 -> 0.23194479 | O7: =0.0001367*(E9*F9*G9)^(0.5425)*Background!J23*3412.142 -> 1100.5799
D8: Rectangular Box Dimensions | E8: Length (ft) | F8: Depth (ft) | G8: Height (ft)
E9: 10 | F9: 10 | G9: 10 | K9: Total Hourly Load | O9: =O4+O5+O6+O7 -> 4745.0081
D10: Floor type | E10: On Grade | K10: Total Load Required | O10: =O9*(100+S4)/100 -> 5219.5089
D11: Box Location | E11: Indoor | K11: Capacity required | O11: =O10*24/S5 -> 6959.3452

Sheet General Walk in Freezer
D3: Input Parameters | E3: Input Values | K3: Output Table
D4: Box Interior Temp (F) | E4: -10 | K4: Wall Load | N4: =O4/O9 -> 0.42742669 | O4: =(1/28.57)*(E5-E4)*(2*E9*G9+2*F9*G9+E9*F9)+IF(E10= "On Grade",Background!U4,Background!U5) -> 2154.1936 | R4: Safety Factor | S4: 10
D5: Box Exterior Temp (F) | E5: 85 | K5: Product Load | N5: =O5/O9 -> 0.035549551 | O5: =E9*F9*G9*0.43*10/24 -> 179.16667 | R5: System Run time | S5: 18
D6: Box Interior RH (%) | E6: 95 | K6: Miscellaneous Load | N6: =O6/O9 -> 0.19178094 | O6: =E9*F9*3.41+INDEX(Background!P4:P20, MATCH(E9*F9*G9, Background!M4:M20,1)) -> 966.55937
D7: Box Exterior RH (%) | E7: 55 | K7: Infiltration Load | N7: =O7/O9 -> 0.34524282 | O7: =0.0001367*(E9*F9*G9)^(0.5425)*Background!T23*3412.142 -> 1739.994
D8: Rectangular Box Dimensions | E8: Length (ft) | F8: Depth (ft) | G8: Height (ft)
E9: 10 | F9: 10 | G9: 10 | K9: Total Hourly Load | O9: =O4+O5+O6+O7 -> 5039.9136
D10: Floor type | E10: On Grade | K10: Total Load Required | O10: =O9*(100+S4)/100 -> 5543.905
D11: Box Location | E11: Indoor | K11: Capacity required | O11: =O10*24/S5 -> 7391.8733

Sheet Convenience Store Cooler
D3: Input Parameters | E3: Input Values | K3: Output Table
D4: Box Interior Temp (F) | E4: 40 | K4: Wall Load | N4: =O4/O9 -> 0.21994748 | O4: =(1/28.57)*(E5-E4)*(2*E9*G9+2*F9*G9+E9*F9)+IF(E10= "On Grade",Background!K29,Background!K30) -> 35659.187 | R4: Safety Factor | S4: 10
D5: Box Exterior Temp (F) | E5: 85 | K5: Product Load | N5: =O5/O9 -> 0.53430693 | O5: =2*E9*F9*G9*10*0.77/16 -> 86625 | R5: System Run time | S5: 16
D6: Box Interior RH (%) | E6: 78 | K6: Miscellaneous Load | N6: =O6/O9 -> 0.12371229 | O6: =E9*F9*3.41+INDEX(Background!F29:F44, MATCH(E9*F9*G9, Background!C29:C44,1)) -> 20056.969
D7: Box Exterior RH (%) | E7: 55 | K7: Infiltration Load | N7: =O7/O9 -> 0.12203329 | O7: =1.7*0.0001367*(E9*F9*G9)^(0.5425)*Background!J48*3412.142 -> 19784.759
D8: Rectangular Box Dimensions | E8: Length (ft) | F8: Depth (ft) | G8: Height (ft)
E9: 60 | F9: 50 | G9: 30 | K9: Total Hourly Load | O9: =O4+O5+O6+O7 -> 162125.91
D10: Floor type | E10: On Grade | K10: Total Load Required | O10: =O9*(100+S4)/100 -> 178338.51
D11: Box Location | E11: Indoor | K11: Capacity required | O11: =O10*24/S5 -> 267507.76

Sheet Produce Cooler
D3: Input Parameters | E3: Input Values | K3: Output Table
D4: Box Interior Temp (F) | E4: 30 | K4: Wall Load | N4: =O4/O9 -> 0.22876075 | O4: =(1/28.57)*(E5-E4)*(2*E9*G9+2*F9*G9+E9*F9)+IF(E10= "On Grade",Background!U29,Background!U30) -> 36117.138 | R4: Safety Factor | S4: 10
D5: Box Exterior Temp (F) | E5: 85 | K5: Product Load | N5: =O5/O9 -> 0.54867027 | O5: =2*E9*F9*G9*10*0.77/16 -> 86625 | R5: System Run time | S5: 16
D6: Box Interior RH (%) | E6: 87 | K6: Miscellaneous Load | N6: =O6/O9 -> 0.12703795 | O6: =E9*F9*3.41+INDEX(Background!P29:P44, MATCH(E9*F9*G9,Background!M29:M44,1)) -> 20056.969
D7: Box Exterior RH (%) | E7: 55 | K7: Infiltration Load | N7: =O7/O9 -> 0.095531027 | O7: =EXP(-0.76578)*((E9*F9*G9)^(0.604316))*(Background!T48^0.855344) -> 15082.602
D8: Rectangular Box Dimensions | E8: Length (ft) | F8: Depth (ft) | G8: Height (ft)
E9: 50 | F9: 60 | G9: 30 | K9: Total Hourly Load | O9: =O4+O5+O6+O7 -> 157881.71
D10: Floor type | E10: On Grade | K10: Total Load Required | O10: =O9*(100+S4)/100 -> 173669.88
D11: Box Location | E11: Indoor | K11: Capacity required | O11: =O10*24/S5 -> 260504.82

Sheet Warehouse Cooler
D3: Input Parameters | E3: Input Values | K3: Output Table
D4: Box Interior Temp (F) | E4: 40 | K4: Wall Load | N4: =O4/O9 -> 0.30348884 | O4: =(1/28.57)*(E5-E4)*(2*E9*G9+2*F9*G9+E9*F9)+IF(E10= "On Grade",Background!K54,Background!K55) -> 34094.467 | R4: Safety Factor | S4: 10
D5: Box Exterior Temp (F) | E5: 85 | K5: Product Load | N5: =O5/O9 -> 0.1069881 | O5: =E9*F9*G9/3.003*10*0.77/24 -> 12019.231 | R5: System Run time | S5: 16
D6: Box Interior RH (%) | E6: 83 | K6: Miscellaneous Load | N6: =O6/O9 -> 0.46228529 | O6: =5500+1190+E9*F9*3.412*2+INDEX(Background!F54:F69, MATCH(E9*F9*G9, Background!C54:C69,1)) -> 51933.938
D7: Box Exterior RH (%) | E7: 55 | K7: Infiltration Load | N7: =O7/O9 -> 0.12723777 | O7: =EXP(-2.12574098749113)*((E9*F9*G9)^(0.671769546909657))*(Background!J73^0.989037300244508) -> 14294.113
D8: Rectangular Box Dimensions | E8: Length (ft) | F8: Depth (ft) | G8: Height (ft)
E9: 75 | F9: 50 | G9: 30 | K9: Total Hourly Load | O9: =O4+O5+O6+O7 -> 112341.75
D10: Floor type | E10: On Grade | K10: Total Load Required | O10: =O9*(100+S4)/100 -> 123575.92
D11: Box Location | E11: Indoor | K11: Capacity required | O11: =O10*24/S5 -> 185363.89

Sheet Warehouse Freezer
D3: Input Parameters | E3: Input Values | K3: Output Table
D4: Box Interior Temp (F) | E4: -20 | K4: Wall Load | N4: =O4/O9 -> 0.37193928 | O4: =(1/28.57)*(E5-E4)*(2*E9*G9+2*F9*G9+E9*F9)+IF(E10= "On Grade",Background!U54,Background!U55) -> 39275.259 | R4: Safety Factor | S4: 10
D5: Box Exterior Temp (F) | E5: 85 | K5: Product Load | N5: =O5/O9 -> 0.025425375 | O5: =E9*F9*G9/3.003*(10*0.43/24) -> 2684.8152 | R5: System Run time | S5: 18
D6: Box Interior RH (%) | E6: 95 | K6: Miscellaneous Load | N6: =O6/O9 -> 0.48477857 | O6: =5500+1880+E9*F9*3.412*2+INDEX(Background!P54:P70, MATCH(E9*F9*G9, Background!M54:M70,1)) -> 51190.625
D7: Box Exterior RH (%) | E7: 55 | K7: Infiltration Load | N7: =O7/O9 -> 0.11785678 | O7: =0.0001299*(E9*F9*G9)^(0.5135)*Background!T73*3412.142 -> 12445.192
D8: Rectangular Box Dimensions | E8: Length (ft) | F8: Depth (ft) | G8: Height (ft)
E9: 90 | F9: 50 | G9: 10 | K9: Total Hourly Load | O9: =O4+O5+O6+O7 -> 105595.89
D10: Floor type | E10: On Grade | K10: Total Load Required | O10: =O9*(100+S4)/100 -> 116155.48
D11: Box Location | E11: Indoor | K11: Capacity required | O11: =O10*24/S5 -> 154873.97

Sheet Floral Cooler
D3: Input Parameters | E3: Input Values | K3: Output Table
D4: Box Interior Temp (F) | E4: 35 | K4: Wall Load | N4: =O4/O9 -> 0.47774888 | O4: =(1/28.57)*(E5-E4)*(2*E9*G9+2*F9*G9+E9*F9)+IF(E10= "On Grade",Background!K79,Background!K80) -> 27957.788 | R4: Safety Factor | S4: 10
D5: Box Exterior Temp (F) | E5: 100 | K5: Product Load | N5: =O5/O9 -> 0.13706178 | O5: =E9*F9*G9*10*0.77/24 -> 8020.8333 | R5: System Run time | S5: 16
D6: Box Interior RH (%) | E6: 87 | K6: Miscellaneous Load | N6: =O6/O9 -> 0.25771281 | O6: =E9*F9*3.412*1+INDEX(Background!F79:F94, MATCH(E9*F9*G9, Background!C79:C94,1)) -> 15081.313
D7: Box Exterior RH (%) | E7: 55 | K7: Infiltration Load | N7: =O7/O9 -> 0.12747653 | O7: =EXP(-0.832116360651863)*((E9*F9*G9)^(0.515379988125453))*(Background!J98^1.01725235117876) -> 7459.9065
D8: Rectangular Box Dimensions | E8: Length (ft) | F8: Depth (ft) | G8: Height (ft)
E9: 50 | F9: 50 | G9: 10 | K9: Total Hourly Load | O9: =O4+O5+O6+O7 -> 58519.841
D10: Floor type | E10: On Grade | K10: Total Load Required | O10: =O9*(100+S4)/100 -> 64371.825
D11: Box Location | E11: Indoor | K11: Capacity required | O11: =O10*24/S5 -> 96557.737

Sheet Produce Warehouse
D3: Input Parameters | E3: Input Values | K3: Output Table
D4: Box Interior Temp (F) | E4: 40 | K4: Wall Load | N4: =O4/O9 -> 0.36993694 | O4: =(1/28.57)*(E5-E4)*(2*E9*G9+2*F9*G9+E9*F9)+IF(E10= "On Grade",Background!U79,Background!U80) -> 36145.095 | R4: Safety Factor | S4: 10
D5: Box Exterior Temp (F) | E5: 95 | K5: Product Load | N5: =O5/O9 -> 0.074153483 | O5: =E9*F9*G9*0.333*10*1.1604/24 -> 7245.2475 | R5: System Run time | S5: 16
D6: Box Interior RH (%) | E6: 85 | K6: Miscellaneous Load | N6: =O6/O9 -> 0.47216176 | O6: =5500+1190+E9*F9*3.412*2+INDEX(Background!P79:P94, MATCH(E9*F9*G9, Background!M79:M94,1)) -> 46133.084
D7: Box Exterior RH (%) | E7: 55 | K7: Infiltration Load | N7: =O7/O9 -> 0.083747816 | O7: =EXP(-0.832116360651863)*((E9*F9*G9)^(0.515379988125453))*(Background!T98^1.01725235117876) -> 8182.6723
D8: Rectangular Box Dimensions | E8: Length (ft) | F8: Depth (ft) | G8: Height (ft)
E9: 50 | F9: 90 | G9: 10 | K9: Total Hourly Load | O9: =O4+O5+O6+O7 -> 97706.098
D10: Floor type | E10: On Grade | K10: Total Load Required | O10: =O9*(100+S4)/100 -> 107476.71
D11: Box Location | E11: Indoor | K11: Capacity required | O11: =O10*24/S5 -> 161215.06

Sheet General Walk-in Cooler with DR
D3: Input Parameters | E3: Input Values | K3: Output Table
D4: Box Interior Temp (F) | E4: 35 | K4: Wall Load | N4: =O4/O9 -> 0.37771594 | O4: =(1/28.57)*(E5-E4)*(2*E9*G9+2*F9*G9+E9*F9)+IF(E10= "On Grade",Background!K4,IF(E10= "Above Grade",Background!K5,Background!K6)) -> 1979.3331 | R4: Safety Factor | S4: 10
D5: Box Exterior Temp (F) | E5: 85 | K5: Product Load | N5: =O5/O9 -> 0.12244918 | O5: =2*E9*F9*G9*0.77*10/24 -> 641.66667 | R5: System Run time | S5: 18
D6: Box Interior RH (%) | E6: 80 | K6: Miscellaneous Load | N6: =O6/O9 -> 0.19530074 | O6: =E9*F9*3.41+INDEX(Background!F4:F19, MATCH(E9*F9*G9, Background!C4:C19,1)) -> 1023.4284
D7: Box Exterior RH (%) | E7: 55 | K7: Infiltration Load | N7: =O7/O9 -> 0.30453414 | O7: =0.0001367*(E9*F9*G9)^(0.5425)*Background!J23*3412.142*1.45*MIN(1+0.2*(E12-1),1.5) -> 1595.8408
D8: Rectangular Box Dimensions | E8: Length (ft) | F8: Depth (ft) | G8: Height (ft)
E9: 10 | F9: 10 | G9: 10 | K9: Total Hourly Load | O9: =O4+O5+O6+O7 -> 5240.269
D10: Floor type | E10: On Grade | K10: Total Load Required | O10: =O9*(100+S4)/100 -> 5764.2959
D11: Box Location | E11: Indoor | K11: Capacity required | O11: =O10*24/S5 -> 7685.7279
D12: Number of Doors | E12: =1 -> 1

Sheet General Walk-in Freezer with DR
D3: Input Parameters | E3: Input Values | K3: Output Table
D4: Box Interior Temp (F) | E4: -10 | K4: Wall Load | N4: =O4/O9 -> 0.36995132 | O4: =(1/28.57)*(E5-E4)*(2*E9*G9+2*F9*G9+E9*F9)+IF(E10= "On Grade",Background!U4,Background!U5) -> 2154.1936 | R4: Safety Factor | S4: 10
D5: Box Exterior Temp (F) | E5: 85 | K5: Product Load | N5: =O5/O9 -> 0.030769261 | O5: =E9*F9*G9*0.43*10/24 -> 179.16667 | R5: System Run time | S5: 18
D6: Box Interior RH (%) | E6: 95 | K6: Miscellaneous Load | N6: =O6/O9 -> 0.16599247 | O6: =E9*F9*3.41+INDEX(Background!P4:P20, MATCH(E9*F9*G9, Background!M4:M20,1)) -> 966.55937
D7: Box Exterior RH (%) | E7: 55 | K7: Infiltration Load | N7: =O7/O9 -> 0.43328695 | O7: =0.0001367*(E9*F9*G9)^(0.5425)*Background!T23*3412.142*1.45*MIN(1+0.15*(E12-1),1.4) -> 2522.9913
D8: Rectangular Box Dimensions | E8: Length (ft) | F8: Depth (ft) | G8: Height (ft)
E9: 10 | F9: 10 | G9: 10 | K9: Total Hourly Load | O9: =O4+O5+O6+O7 -> 5822.9109
D10: Floor type | E10: On Grade | K10: Total Load Required | O10: =O9*(100+S4)/100 -> 6405.202
D11: Box Location | E11: Indoor | K11: Capacity required | O11: =O10*24/S5 -> 8540.2693
D12: Number of Doors | E12: 1

Sheet Background
C2: General Walk in Cooler | M2: General Walk in Freezer
C3: Volume Range | D3: Rated Power | E3: Quantity | F3: Load | I3: Floor type | J3: Teff | K3: Q floor | M3: Volume Range | N3: Rated Power | O3: Quantity | P3: Load | S3: Floor type | T3: Teff | U3: Q floor
C4: 0 | D4: 100 | E4: 1 | F4: =D4*E4*3.412142 -> 341.2142 | I4: On Grade | J4: =(1.8408+0.5148*(J17-J18))*(('General Walk in Cooler'!E9*'General Walk in Cooler'!F9)^(0.679)/(200^0.679)) -> 17.226914 | K4: =64.1025641*J4 -> 1104.2894 | M4: 0 | N4: 100 | O4: 1 | P4: =N4*O4*22*3.412142/24 -> 312.77968 | S4: On Grade | T4: =(1.8408+0.5148*(T17-T18))*(('General Walk in Freezer'!E9*'General Walk in Freezer'!F9)^(0.679)/(200^0.679)) -> 31.696353 | U4: =2*7.755*T4 -> 491.61043
C5: 600 | D5: 100 | E5: 2 | F5: =D5*E5*3.412142 -> 682.4284 | I5: Above Grade | K5: =(1/3.12)*'General Walk in Cooler'!E9*'General Walk in Cooler'!F9*(J17-J18) -> 1602.5641 | M5: 600 | N5: 100 | O5: 2 | P5: =N5*O5*22*3.412142/24 -> 625.55937 | S5: Above Grade | U5: =(1/32.32)*'General Walk in Freezer'!E9*'General Walk in Freezer'!F9*(T17-T18) -> 293.93564
C6: 1350 | D6: 100 | E6: 3 | F6: =D6*E6*3.412142 -> 1023.6426 | I6: Above Grade (No gap) | J6: =(1.8408+0.5148*(J17-J18))*(('General Walk in Cooler'!E9*'General Walk in Cooler'!F9)^(0.679)/(200^0.679)) -> 17.226914 | K6: =(1/2)*64.1025641*J4 -> 552.14469 | M6: 1350 | N6: 100 | O6: 3 | P6: =N6*O6*22*3.412142/24 -> 938.33905
C7: 2570 | D7: 100 | E7: 4 | F7: =D7*E7*3.412142 -> 1364.8568 | M7: 2570 | N7: 100 | O7: 4 | P7: =N7*O7*22*3.412142/24 -> 1251.1187
C8: 4810 | D8: 100 | E8: 5 | F8: =D8*E8*3.412142 -> 1706.071 | I8: Tc_out | J8: =(J17-32)/1.8 -> 29.444444 | M8: 3210 | N8: 100 | O8: 5 | P8: =N8*O8*22*3.412142/24 -> 1563.8984 | S8: Tc_out | T8: =(T17-32)/1.8 -> 29.444444
C9: 5770 | D9: 100 | E9: 6 | F9: =D9*E9*3.412142 -> 2047.2852 | I9: Tc_in | J9: =(J18-32)/1.8 -> 1.6666667 | M9: 4810 | N9: 100 | O9: 6 | P9: =N9*O9*22*3.412142/24 -> 1876.6781 | S9: Tc_in | T9: =(T18-32)/1.8 -> -23.333333
C10: 6260 | D10: 320 | E10: 2 | F10: =D10*E10*3.412142 -> 2183.7709 | I10: W_out | J10: =0.622*J14/(101.325-J14) -> 0.014167414 | M10: 5770 | N10: 320 | O10: 2 | P10: =N10*O10*22*3.412142/24 -> 2001.79 | S10: W_out | T10: =0.622*T14/(101.325-T14) -> 0.014167414
C11: 12100 | D11: 320 | E11: 3 | F11: =D11*E11*3.412142 -> 3275.6563 | I11: W_in | J11: =0.622*J15/(101.325-J15) -> 0.0034027726 | M11: 6260 | N11: 320 | O11: 3 | P11: =N11*O11*22*3.412142/24 -> 3002.685 | S11: W_in | T11: =0.622*T15/(101.325-T15) -> 0.00054921382
C12: 16900 | D12: 320 | E12: 4 | F12: =D12*E12*3.412142 -> 4367.5418 | M12: 15010 | N12: 320 | O12: 4 | P12: =N12*O12*22*3.412142/24 -> 4003.5799
C13: 21700 | D13: 320 | E13: 6 | F13: =D13*E13*3.412142 -> 6551.3126 | M13: 21700 | N13: 960 | O13: 2 | P13: =N13*O13*22*3.412142/24 -> 6005.3699
C14: 36100 | D14: 320 | E14: 8 | F14: =D14*E14*3.412142 -> 8735.0835 | I14: e_out | J14: =('General Walk in Cooler'!E7*0.6112*EXP(17.625*J8/(243.12+J8))/100) -> 2.2565022 | M14: 27500 | N14: 960 | O14: 3 | P14: =N14*O14*22*3.412142/24 -> 9008.0549 | S14: e_out | T14: =('General Walk in Freezer'!E7*0.6112*EXP(17.625*T8/(243.12+T8))/100) -> 2.2565022
C15: 45100 | D15: 960 | E15: 2 | F15: =D15*E15*3.412142 -> 6551.3126 | I15: e_in | J15: =('General Walk in Cooler'!E6*0.6112*EXP(17.625*J9/(243.12+J9))/100) -> 0.55130221 | M15: 36100 | N15: 960 | O15: 4 | P15: =N15*O15*22*3.412142/24 -> 12010.74 | S15: e_in | T15: =('General Walk in Freezer'!E6*0.6112*EXP(17.625*T9/(243.12+T9))/100) -> 0.089389062
C16: 58100 | D16: 960 | E16: 3 | F16: =D16*E16*3.412142 -> 9826.969 | M16: 58100 | N16: 960 | O16: 6 | P16: =N16*O16*22*3.412142/24 -> 18016.11
C17: 105100 | D17: 960 | E17: 6 | F17: =D17*E17*3.412142 -> 19653.938 | I17: Tf_out | J17: ='General Walk in Cooler'!E5 -> 85 | M17: 105100 | N17: 960 | O17: 6 | P17: =N17*O17*22*3.412142/24 -> 18016.11 | S17: Tf_out | T17: ='General Walk in Freezer'!E5 -> 85
C18: 155000 | D18: 960 | E18: 8 | F18: =D18*E18*3.412142 -> 26205.251 | I18: Tf_in | J18: ='General Walk in Cooler'!E4 -> 35 | M18: 155000 | N18: 960 | O18: 6 | P18: =N18*O18*22*3.412142/24 -> 18016.11 | S18: Tf_in | T18: ='General Walk in Freezer'!E4 -> -10
C19: 10000000000 | F19: NA | M19: 177500 | N19: 960 | O19: 12 | P19: =N19*O19*22*3.412142/24 -> 36032.22
I20: h_out | J20: =1.006*J8+J10*(2501+1.86*J8) -> 65.829715 | M20: 10000000000 | P20: NA | S20: h_out | T20: =1.006*T8+T10*(2501+1.86*T8) -> 65.829715
I21: h_in | J21: =1.006*J9+J11*(2501+1.86*J9) -> 10.197549 | S21: h_in | T21: =1.006*T9+T11*(2501+1.86*T9) -> -22.123585
I23: dh | J23: =J20-J21 -> 55.632165 | S23: dh | T23: =T20-T21 -> 87.9533
C27: Convenience Store Cooler | M27: Produce Cooler
C28: Volume Range | D28: Rated Power | E28: Quantity | F28: Load | I28: Floor type | J28: Teff | K28: Q floor | M28: Volume Range | N28: Rated Power | O28: Quantity | P28: Load | S28: Floor type | T28: Teff | U28: Q floor
C29: 0 | D29: 100 | E29: 1 | F29: =D29*E29*3.412142 -> 341.2142 | I29: On Grade | J29: =(1.8408+0.5148*(J42-J43))*(('Convenience Store Cooler'!E9*'Convenience Store Cooler'!F9)^(0.679)/(200^0.679)) -> 157.26211 | K29: =2*65.3*J29 -> 20538.431 | M29: 0 | N29: 100 | O29: 1 | P29: =N29*O29*3.412142 -> 341.2142 | S29: On Grade | T29: =(1.8408+0.5148*(T42-T43))*(('Produce Cooler'!E9*'Produce Cooler'!F9)^(0.679)/(200^0.679)) -> 189.63671 | U29: =2*46.5*T29 -> 17636.214
C30: 600 | D30: 100 | E30: 2 | F30: =D30*E30*3.412142 -> 682.4284 | I30: Above Grade | K30: =(1/3.12)*'Convenience Store Cooler'!E9*'Convenience Store Cooler'!F9*(J42-J43) -> 43269.231 | M30: 600 | N30: 100 | O30: 2 | P30: =N30*O30*3.412142 -> 682.4284 | S30: Above Grade | U30: =(1/3.12)*'Produce Cooler'!E9*'Produce Cooler'!F9*(T42-T43) -> 52884.615
C31: 1350 | D31: 100 | E31: 3 | F31: =D31*E31*3.412142 -> 1023.6426 | M31: 1350 | N31: 100 | O31: 3 | P31: =N31*O31*3.412142 -> 1023.6426
C32: 2570 | D32: 100 | E32: 4 | F32: =D32*E32*3.412142 -> 1364.8568 | M32: 2570 | N32: 100 | O32: 4 | P32: =N32*O32*3.412142 -> 1364.8568
C33: 4810 | D33: 100 | E33: 5 | F33: =D33*E33*3.412142 -> 1706.071 | I33: Tc_out | J33: =(J42-32)/1.8 -> 29.444444 | M33: 4810 | N33: 100 | O33: 5 | P33: =N33*O33*3.412142 -> 1706.071 | S33: Tc_out | T33: =(T42-32)/1.8 -> 29.444444
C34: 5770 | D34: 100 | E34: 6 | F34: =D34*E34*3.412142 -> 2047.2852 | I34: Tc_in | J34: =(J43-32)/1.8 -> 4.4444444 | M34: 5770 | N34: 100 | O34: 6 | P34: =N34*O34*3.412142 -> 2047.2852 | S34: Tc_in | T34: =(T43-32)/1.8 -> -1.1111111
C35: 6260 | D35: 320 | E35: 2 | F35: =D35*E35*3.412142 -> 2183.7709 | I35: W_out | J35: =0.622*J39/(101.325-J39) -> 0.014167414 | M35: 6260 | N35: 320 | O35: 2 | P35: =N35*O35*3.412142 -> 2183.7709 | S35: W_out | T35: =0.622*T39/(101.325-T39) -> 0.014167414
C36: 12100 | D36: 320 | E36: 3 | F36: =D36*E36*3.412142 -> 3275.6563 | I36: W_in | J36: =0.622*J40/(101.325-J40) -> 0.0040418706 | M36: 12100 | N36: 320 | O36: 3 | P36: =N36*O36*3.412142 -> 3275.6563 | S36: W_in | T36: =0.622*T40/(101.325-T40) -> 0.0030251045
C37: 16900 | D37: 320 | E37: 4 | F37: =D37*E37*3.412142 -> 4367.5418 | M37: 16900 | N37: 320 | O37: 4 | P37: =N37*O37*3.412142 -> 4367.5418
C38: 21700 | D38: 320 | E38: 6 | F38: =D38*E38*3.412142 -> 6551.3126 | M38: 21700 | N38: 320 | O38: 6 | P38: =N38*O38*3.412142 -> 6551.3126
C39: 36100 | D39: 320 | E39: 8 | F39: =D39*E39*3.412142 -> 8735.0835 | I39: e_out | J39: =('Convenience Store Cooler'!E7*0.6112*EXP(17.625*J33/(243.12+J33))/100) -> 2.2565022 | M39: 36100 | N39: 320 | O39: 8 | P39: =N39*O39*3.412142 -> 8735.0835 | S39: e_out | T39: =('Produce Cooler'!E7*0.6112*EXP(17.625*T33/(243.12+T33))/100) -> 2.2565022
C40: 45100 | D40: 960 | E40: 2 | F40: =D40*E40*3.412142 -> 6551.3126 | I40: e_in | J40: =('Convenience Store Cooler'!E6*0.6112*EXP(17.625*J34/(243.12+J34))/100) -> 0.65417756 | M40: 45100 | N40: 960 | O40: 2 | P40: =N40*O40*3.412142 -> 6551.3126 | S40: e_in | T40: =('Produce Cooler'!E6*0.6112*EXP(17.625*T34/(243.12+T34))/100) -> 0.49041025
C41: 58100 | D41: 960 | E41: 3 | F41: =D41*E41*3.412142 -> 9826.969 | M41: 58100 | N41: 960 | O41: 3 | P41: =N41*O41*3.412142 -> 9826.969
C42: 105100 | D42: 960 | E42: 6 | F42: =D42*E42*3.412142 -> 19653.938 | I42: Tf_out | J42: ='Convenience Store Cooler'!E5 -> 85 | M42: 105100 | N42: 960 | O42: 6 | P42: =N42*O42*3.412142 -> 19653.938 | S42: Tf_out | T42: ='Produce Cooler'!E5 -> 85
C43: 155000 | D43: 960 | E43: 8 | F43: =D43*E43*3.412142 -> 26205.251 | I43: Tf_in | J43: ='Convenience Store Cooler'!E4 -> 40 | M43: 155000 | N43: 960 | O43: 8 | P43: =N43*O43*3.412142 -> 26205.251 | S43: Tf_in | T43: ='Produce Cooler'!E4 -> 30
C44: 10000000000 | F44: NA | M44: 10000000000 | P44: NA
I45: h_out | J45: =1.006*J33+J35*(2501+1.86*J33) -> 65.829715 | S45: h_out | T45: =1.006*T33+T35*(2501+1.86*T33) -> 65.829715
...
